Workbook

Sheet DesignSheet
A1: Cycloidal Drive – SolidWorks Equation Generator (Epitrochoid + Roller Offset)
A3: Inputs
A4: Number of ring rollers (pins) | B4: N_pins | C4: 10 | D4: count
A5: Ring pitch circle diameter | B5: PCD | C5: 30 | D5: mm
A6: Roller (pin) diameter | B6: d_roller | C6: 3 | D6: mm
A7: Eccentricity | B7: E | C7: 0.75 | D7: mm
A8: Disc phase offset | B8: phi | C8: 0 | D8: deg (0 for disc1, 180 for disc2)
A9: Sample points per revolution | B9: n_pts | C9: 361 | D9: count
A11: Derived
A12: Tooth (lobe) count | B12: n | C12: =C4-1 -> 9 | D12: count
A13: Ring radius | B13: R | C13: =C5/2 -> 15 | D13: mm
A14: Pitch parameter (R/N_pins) | B14: p | C14: =(C5/2)/C4 -> 1.5 | D14: mm
A15: Nominal reduction ratio | B15: ratio | C15: =C4/(C4-1) -> 1.1111111 | D15: N/(N-1)
A16: Roller radius | B16: r_roller | C16: =C6/2 -> 1.5 | D16: mm
A17: Phi (rad) | B17: phi_rad | C17: =RADIANS(C8) -> 0 | D17: rad
A20: SolidWorks Equation Driven Curve (t in radians, 0→2π)
A21: x(t) = | B21: =_xlfn.CONCAT("(",C11,"*",C13,")*cos(t+",C16,") + ",C7,"*cos((",C11,"+1)*(t+",C16,")) - (",C6,"/2)*cos(atan( sin(",C11,"*(t+",C16,")) / ( cos(",C11,"*(t+",C16,")) + (",C11,"*",C13,")/(",C7,"*(",C11,"+1)) ) ) + (t+",C16,"))") -> (*15)*cos(t+1.5) + 0.75*cos((+1)*(t+1.5)) - (3/2)*cos(atan( sin(*(t+1.5)) / ( cos(*(t+1.5)) + (*15)/(0.75*(+1)) ) ) + (t+1.5))
A23: y(t) = | B23: =_xlfn.CONCAT("(",C11,"*",C13,")*sin(t+",C16,") + ",C7,"*sin((",C11,"+1)*(t+",C16,")) - (",C6,"/2)*sin(atan( sin(",C11,"*(t+",C16,")) / ( cos(",C11,"*(t+",C16,")) + (",C11,"*",C13,")/(",C7,"*(",C11,"+1)) ) ) + (t+",C16,"))") -> (*15)*sin(t+1.5) + 0.75*sin((+1)*(t+1.5)) - (3/2)*sin(atan( sin(*(t+1.5)) / ( cos(*(t+1.5)) + (*15)/(0.75*(+1)) ) ) + (t+1.5))
A25: Copy/paste into SolidWorks: | B25: Insert → Curve → Equation Driven Curve → Parametric; set t range 0 to 2*pi; set z(t)=0; paste x(t), y(t).

Sheet PointTable
A1: t (rad) | B1: x (mm) | C1: y (mm)
A2: =2*PI()*0/(DesignSheet!C9-1) -> 0 | B2: =(DesignSheet!C11*DesignSheet!C13)*COS((A2+DesignSheet!C16)) + (DesignSheet!C7)*COS((DesignSheet!C11+1)*(A2+DesignSheet!C16)) - (DesignSheet!C6/2)*COS(ATAN( SIN(DesignSheet!C11*(A2+DesignSheet!C16)) / ( COS(DesignSheet!C11*(A2+DesignSheet!C16)) + (DesignSheet!C11*DesignSheet!C13)/(DesignSheet!C7*(DesignSheet!C11+1)) ) )+(A2+DesignSheet!C16)) -> -0.053052901 | C2: =(DesignSheet!C11*DesignSheet!C13)*SIN((A2+DesignSheet!C16)) + (DesignSheet!C7)*SIN((DesignSheet!C11+1)*(A2+DesignSheet!C16)) - (DesignSheet!C6/2)*SIN(ATAN( SIN(DesignSheet!C11*(A2+DesignSheet!C16)) / ( COS(DesignSheet!C11*(A2+DesignSheet!C16)) + (DesignSheet!C11*DesignSheet!C13)/(DesignSheet!C7*(DesignSheet!C11+1)) ) )+(A2+DesignSheet!C16)) -> -0.74812124
A3: =2*PI()*1/(DesignSheet!C9-1) -> 0.017453293 | B3: =(DesignSheet!C11*DesignSheet!C13)*COS((A3+DesignSheet!C16)) + (DesignSheet!C7)*COS((DesignSheet!C11+1)*(A3+DesignSheet!C16)) - (DesignSheet!C6/2)*COS(ATAN( SIN(DesignSheet!C11*(A3+DesignSheet!C16)) / ( COS(DesignSheet!C11*(A3+DesignSheet!C16)) + (DesignSheet!C11*DesignSheet!C13)/(DesignSheet!C7*(DesignSheet!C11+1)) ) )+(A3+DesignSheet!C16)) -> -0.039988305 | C3: =(DesignSheet!C11*DesignSheet!C13)*SIN((A3+DesignSheet!C16)) + (DesignSheet!C7)*SIN((DesignSheet!C11+1)*(A3+DesignSheet!C16)) - (DesignSheet!C6/2)*SIN(ATAN( SIN(DesignSheet!C11*(A3+DesignSheet!C16)) / ( COS(DesignSheet!C11*(A3+DesignSheet!C16)) + (DesignSheet!C11*DesignSheet!C13)/(DesignSheet!C7*(DesignSheet!C11+1)) ) )+(A3+DesignSheet!C16)) -> -0.7489332
A4: =2*PI()*2/(DesignSheet!C9-1) -> 0.034906585 | B4: =(DesignSheet!C11*DesignSheet!C13)*COS((A4+DesignSheet!C16)) + (DesignSheet!C7)*COS((DesignSheet!C11+1)*(A4+DesignSheet!C16)) - (DesignSheet!C6/2)*COS(ATAN( SIN(DesignSheet!C11*(A4+DesignSheet!C16)) / ( COS(DesignSheet!C11*(A4+DesignSheet!C16)) + (DesignSheet!C11*DesignSheet!C13)/(DesignSheet!C7*(DesignSheet!C11+1)) ) )+(A4+DesignSheet!C16)) -> -0.026911528 | C4: =(DesignSheet!C11*DesignSheet!C13)*SIN((A4+DesignSheet!C16)) + (DesignSheet!C7)*SIN((DesignSheet!C11+1)*(A4+DesignSheet!C16)) - (DesignSheet!C6/2)*SIN(ATAN( SIN(DesignSheet!C11*(A4+DesignSheet!C16)) / ( COS(DesignSheet!C11*(A4+DesignSheet!C16)) + (DesignSheet!C11*DesignSheet!C13)/(DesignSheet!C7*(DesignSheet!C11+1)) ) )+(A4+DesignSheet!C16)) -> -0.74951702
A5: =2*PI()*3/(DesignSheet!C9-1) -> 0.052359878 | B5: =(DesignSheet!C11*DesignSheet!C13)*COS((A5+DesignSheet!C16)) + (DesignSheet!C7)*COS((DesignSheet!C11+1)*(A5+DesignSheet!C16)) - (DesignSheet!C6/2)*COS(ATAN( SIN(DesignSheet!C11*(A5+DesignSheet!C16)) / ( COS(DesignSheet!C11*(A5+DesignSheet!C16)) + (DesignSheet!C11*DesignSheet!C13)/(DesignSheet!C7*(DesignSheet!C11+1)) ) )+(A5+DesignSheet!C16)) -> -0.013826554 | C5: =(DesignSheet!C11*DesignSheet!C13)*SIN((A5+DesignSheet!C16)) + (DesignSheet!C7)*SIN((DesignSheet!C11+1)*(A5+DesignSheet!C16)) - (DesignSheet!C6/2)*SIN(ATAN( SIN(DesignSheet!C11*(A5+DesignSheet!C16)) / ( COS(DesignSheet!C11*(A5+DesignSheet!C16)) + (DesignSheet!C11*DesignSheet!C13)/(DesignSheet!C7*(DesignSheet!C11+1)) ) )+(A5+DesignSheet!C16)) -> -0.74987254
A6: =2*PI()*4/(DesignSheet!C9-1) -> 0.06981317 | B6: =(DesignSheet!C11*DesignSheet!C13)*COS((A6+DesignSheet!C16)) + (DesignSheet!C7)*COS((DesignSheet!C11+1)*(A6+DesignSheet!C16)) - (DesignSheet!C6/2)*COS(ATAN( SIN(DesignSheet!C11*(A6+DesignSheet!C16)) / ( COS(DesignSheet!C11*(A6+DesignSheet!C16)) + (DesignSheet!C11*DesignSheet!C13)/(DesignSheet!C7*(DesignSheet!C11+1)) ) )+(A6+DesignSheet!C16)) -> -0.00073736742 | C6: =(DesignSheet!C11*DesignSheet!C13)*SIN((A6+DesignSheet!C16)) + (DesignSheet!C7)*SIN((DesignSheet!C11+1)*(A6+DesignSheet!C16)) - (DesignSheet!C6/2)*SIN(ATAN( SIN(DesignSheet!C11*(A6+DesignSheet!C16)) / ( COS(DesignSheet!C11*(A6+DesignSheet!C16)) + (DesignSheet!C11*DesignSheet!C13)/(DesignSheet!C7*(DesignSheet!C11+1)) ) )+(A6+DesignSheet!C16)) -> -0.74999964
A7: =2*PI()*5/(DesignSheet!C9-1) -> 0.087266463 | B7: =(DesignSheet!C11*DesignSheet!C13)*COS((A7+DesignSheet!C16)) + (DesignSheet!C7)*COS((DesignSheet!C11+1)*(A7+DesignSheet!C16)) - (DesignSheet!C6/2)*COS(ATAN( SIN(DesignSheet!C11*(A7+DesignSheet!C16)) / ( COS(DesignSheet!C11*(A7+DesignSheet!C16)) + (DesignSheet!C11*DesignSheet!C13)/(DesignSheet!C7*(DesignSheet!C11+1)) ) )+(A7+DesignSheet!C16)) -> 0.012352043 | C7: =(DesignSheet!C11*DesignSheet!C13)*SIN((A7+DesignSheet!C16)) + (DesignSheet!C7)*SIN((DesignSheet!C11+1)*(A7+DesignSheet!C16)) - (DesignSheet!C6/2)*SIN(ATAN( SIN(DesignSheet!C11*(A7+DesignSheet!C16)) / ( COS(DesignSheet!C11*(A7+DesignSheet!C16)) + (DesignSheet!C11*DesignSheet!C13)/(DesignSheet!C7*(DesignSheet!C11+1)) ) )+(A7+DesignSheet!C16)) -> -0.74989828
A8: =2*PI()*6/(DesignSheet!C9-1) -> 0.10471976 | B8: =(DesignSheet!C11*DesignSheet!C13)*COS((A8+DesignSheet!C16)) + (DesignSheet!C7)*COS((DesignSheet!C11+1)*(A8+DesignSheet!C16)) - (DesignSheet!C6/2)*COS(ATAN( SIN(DesignSheet!C11*(A8+DesignSheet!C16)) / ( COS(DesignSheet!C11*(A8+DesignSheet!C16)) + (DesignSheet!C11*DesignSheet!C13)/(DesignSheet!C7*(DesignSheet!C11+1)) ) )+(A8+DesignSheet!C16)) -> 0.025437692 | C8: =(DesignSheet!C11*DesignSheet!C13)*SIN((A8+DesignSheet!C16)) + (DesignSheet!C7)*SIN((DesignSheet!C11+1)*(A8+DesignSheet!C16)) - (DesignSheet!C6/2)*SIN(ATAN( SIN(DesignSheet!C11*(A8+DesignSheet!C16)) / ( COS(DesignSheet!C11*(A8+DesignSheet!C16)) + (DesignSheet!C11*DesignSheet!C13)/(DesignSheet!C7*(DesignSheet!C11+1)) ) )+(A8+DesignSheet!C16)) -> -0.74956849
A9: =2*PI()*7/(DesignSheet!C9-1) -> 0.12217305 | B9: =(DesignSheet!C11*DesignSheet!C13)*COS((A9+DesignSheet!C16)) + (DesignSheet!C7)*COS((DesignSheet!C11+1)*(A9+DesignSheet!C16)) - (DesignSheet!C6/2)*COS(ATAN( SIN(DesignSheet!C11*(A9+DesignSheet!C16)) / ( COS(DesignSheet!C11*(A9+DesignSheet!C16)) + (DesignSheet!C11*DesignSheet!C13)/(DesignSheet!C7*(DesignSheet!C11+1)) ) )+(A9+DesignSheet!C16)) -> 0.038515591 | C9: =(DesignSheet!C11*DesignSheet!C13)*SIN((A9+DesignSheet!C16)) + (DesignSheet!C7)*SIN((DesignSheet!C11+1)*(A9+DesignSheet!C16)) - (DesignSheet!C6/2)*SIN(ATAN( SIN(DesignSheet!C11*(A9+DesignSheet!C16)) / ( COS(DesignSheet!C11*(A9+DesignSheet!C16)) + (DesignSheet!C11*DesignSheet!C13)/(DesignSheet!C7*(DesignSheet!C11+1)) ) )+(A9+DesignSheet!C16)) -> -0.74901038
A10: =2*PI()*8/(DesignSheet!C9-1) -> 0.13962634 | B10: =(DesignSheet!C11*DesignSheet!C13)*COS((A10+DesignSheet!C16)) + (DesignSheet!C7)*COS((DesignSheet!C11+1)*(A10+DesignSheet!C16)) - (DesignSheet!C6/2)*COS(ATAN( SIN(DesignSheet!C11*(A10+DesignSheet!C16)) / ( COS(DesignSheet!C11*(A10+DesignSheet!C16)) + (DesignSheet!C11*DesignSheet!C13)/(DesignSheet!C7*(DesignSheet!C11+1)) ) )+(A10+DesignSheet!C16)) -> 0.051581759 | C10: =(DesignSheet!C11*DesignSheet!C13)*SIN((A10+DesignSheet!C16)) + (DesignSheet!C7)*SIN((DesignSheet!C11+1)*(A10+DesignSheet!C16)) - (DesignSheet!C6/2)*SIN(ATAN( SIN(DesignSheet!C11*(A10+DesignSheet!C16)) / ( COS(DesignSheet!C11*(A10+DesignSheet!C16)) + (DesignSheet!C11*DesignSheet!C13)/(DesignSheet!C7*(DesignSheet!C11+1)) ) )+(A10+DesignSheet!C16)) -> -0.74822411
A11: =2*PI()*9/(DesignSheet!C9-1) -> 0.15707963 | B11: =(DesignSheet!C11*DesignSheet!C13)*COS((A11+DesignSheet!C16)) + (DesignSheet!C7)*COS((DesignSheet!C11+1)*(A11+DesignSheet!C16)) - (DesignSheet!C6/2)*COS(ATAN( SIN(DesignSheet!C11*(A11+DesignSheet!C16)) / ( COS(DesignSheet!C11*(A11+DesignSheet!C16)) + (DesignSheet!C11*DesignSheet!C13)/(DesignSheet!C7*(DesignSheet!C11+1)) ) )+(A11+DesignSheet!C16)) -> 0.064632214 | C11: =(DesignSheet!C11*DesignSheet!C13)*SIN((A11+DesignSheet!C16)) + (DesignSheet!C7)*SIN((DesignSheet!C11+1)*(A11+DesignSheet!C16)) - (DesignSheet!C6/2)*SIN(ATAN( SIN(DesignSheet!C11*(A11+DesignSheet!C16)) / ( COS(DesignSheet!C11*(A11+DesignSheet!C16)) + (DesignSheet!C11*DesignSheet!C13)/(DesignSheet!C7*(DesignSheet!C11+1)) ) )+(A11+DesignSheet!C16)) -> -0.74720993
A12: =2*PI()*10/(DesignSheet!C9-1) -> 0.17453293 | B12: =(DesignSheet!C11*DesignSheet!C13)*COS((A12+DesignSheet!C16)) + (DesignSheet!C7)*COS((DesignSheet!C11+1)*(A12+DesignSheet!C16)) - (DesignSheet!C6/2)*COS(ATAN( SIN(DesignSheet!C11*(A12+DesignSheet!C16)) / ( COS(DesignSheet!C11*(A12+DesignSheet!C16)) + (DesignSheet!C11*DesignSheet!C13)/(DesignSheet!C7*(DesignSheet!C11+1)) ) )+(A12+DesignSheet!C16)) -> 0.077662982 | C12: =(DesignSheet!C11*DesignSheet!C13)*SIN((A12+DesignSheet!C16)) + (DesignSheet!C7)*SIN((DesignSheet!C11+1)*(A12+DesignSheet!C16)) - (DesignSheet!C6/2)*SIN(ATAN( SIN(DesignSheet!C11*(A12+DesignSheet!C16)) / ( COS(DesignSheet!C11*(A12+DesignSheet!C16)) + (DesignSheet!C11*DesignSheet!C13)/(DesignSheet!C7*(DesignSheet!C11+1)) ) )+(A12+DesignSheet!C16)) -> -0.74596814
A13: =2*PI()*11/(DesignSheet!C9-1) -> 0.19198622 | B13: =(DesignSheet!C11*DesignSheet!C13)*COS((A13+DesignSheet!C16)) + (DesignSheet!C7)*COS((DesignSheet!C11+1)*(A13+DesignSheet!C16)) - (DesignSheet!C6/2)*COS(ATAN( SIN(DesignSheet!C11*(A13+DesignSheet!C16)) / ( COS(DesignSheet!C11*(A13+DesignSheet!C16)) + (DesignSheet!C11*DesignSheet!C13)/(DesignSheet!C7*(DesignSheet!C11+1)) ) )+(A13+DesignSheet!C16)) -> 0.090670092 | C13: =(DesignSheet!C11*DesignSheet!C13)*SIN((A13+DesignSheet!C16)) + (DesignSheet!C7)*SIN((DesignSheet!C11+1)*(A13+DesignSheet!C16)) - (DesignSheet!C6/2)*SIN(ATAN( SIN(DesignSheet!C11*(A13+DesignSheet!C16)) / ( COS(DesignSheet!C11*(A13+DesignSheet!C16)) + (DesignSheet!C11*DesignSheet!C13)/(DesignSheet!C7*(DesignSheet!C11+1)) ) )+(A13+DesignSheet!C16)) -> -0.74449912
A14: =2*PI()*12/(DesignSheet!C9-1) -> 0.20943951 | B14: =(DesignSheet!C11*DesignSheet!C13)*COS((A14+DesignSheet!C16)) + (DesignSheet!C7)*COS((DesignSheet!C11+1)*(A14+DesignSheet!C16)) - (DesignSheet!C6/2)*COS(ATAN( SIN(DesignSheet!C11*(A14+DesignSheet!C16)) / ( COS(DesignSheet!C11*(A14+DesignSheet!C16)) + (DesignSheet!C11*DesignSheet!C13)/(DesignSheet!C7*(DesignSheet!C11+1)) ) )+(A14+DesignSheet!C16)) -> 0.10364958 | C14: =(DesignSheet!C11*DesignSheet!C13)*SIN((A14+DesignSheet!C16)) + (DesignSheet!C7)*SIN((DesignSheet!C11+1)*(A14+DesignSheet!C16)) - (DesignSheet!C6/2)*SIN(ATAN( SIN(DesignSheet!C11*(A14+DesignSheet!C16)) / ( COS(DesignSheet!C11*(A14+DesignSheet!C16)) + (DesignSheet!C11*DesignSheet!C13)/(DesignSheet!C7*(DesignSheet!C11+1)) ) )+(A14+DesignSheet!C16)) -> -0.74280331
A15: =2*PI()*13/(DesignSheet!C9-1) -> 0.2268928 | B15: =(DesignSheet!C11*DesignSheet!C13)*COS((A15+DesignSheet!C16)) + (DesignSheet!C7)*COS((DesignSheet!C11+1)*(A15+DesignSheet!C16)) - (DesignSheet!C6/2)*COS(ATAN( SIN(DesignSheet!C11*(A15+DesignSheet!C16)) / ( COS(DesignSheet!C11*(A15+DesignSheet!C16)) + (DesignSheet!C11*DesignSheet!C13)/(DesignSheet!C7*(DesignSheet!C11+1)) ) )+(A15+DesignSheet!C16)) -> 0.1165975 | C15: =(DesignSheet!C11*DesignSheet!C13)*SIN((A15+DesignSheet!C16)) + (DesignSheet!C7)*SIN((DesignSheet!C11+1)*(A15+DesignSheet!C16)) - (DesignSheet!C6/2)*SIN(ATAN( SIN(DesignSheet!C11*(A15+DesignSheet!C16)) / ( COS(DesignSheet!C11*(A15+DesignSheet!C16)) + (DesignSheet!C11*DesignSheet!C13)/(DesignSheet!C7*(DesignSheet!C11+1)) ) )+(A15+DesignSheet!C16)) -> -0.74088125
A16: =2*PI()*14/(DesignSheet!C9-1) -> 0.2443461 | B16: =(DesignSheet!C11*DesignSheet!C13)*COS((A16+DesignSheet!C16)) + (DesignSheet!C7)*COS((DesignSheet!C11+1)*(A16+DesignSheet!C16)) - (DesignSheet!C6/2)*COS(ATAN( SIN(DesignSheet!C11*(A16+DesignSheet!C16)) / ( COS(DesignSheet!C11*(A16+DesignSheet!C16)) + (DesignSheet!C11*DesignSheet!C13)/(DesignSheet!C7*(DesignSheet!C11+1)) ) )+(A16+DesignSheet!C16)) -> 0.12950991 | C16: =(DesignSheet!C11*DesignSheet!C13)*SIN((A16+DesignSheet!C16)) + (DesignSheet!C7)*SIN((DesignSheet!C11+1)*(A16+DesignSheet!C16)) - (DesignSheet!C6/2)*SIN(ATAN( SIN(DesignSheet!C11*(A16+DesignSheet!C16)) / ( COS(DesignSheet!C11*(A16+DesignSheet!C16)) + (DesignSheet!C11*DesignSheet!C13)/(DesignSheet!C7*(DesignSheet!C11+1)) ) )+(A16+DesignSheet!C16)) -> -0.7387335
A17: =2*PI()*15/(DesignSheet!C9-1) -> 0.26179939 | B17: =(DesignSheet!C11*DesignSheet!C13)*COS((A17+DesignSheet!C16)) + (DesignSheet!C7)*COS((DesignSheet!C11+1)*(A17+DesignSheet!C16)) - (DesignSheet!C6/2)*COS(ATAN( SIN(DesignSheet!C11*(A17+DesignSheet!C16)) / ( COS(DesignSheet!C11*(A17+DesignSheet!C16)) + (DesignSheet!C11*DesignSheet!C13)/(DesignSheet!C7*(DesignSheet!C11+1)) ) )+(A17+DesignSheet!C16)) -> 0.14238286 | C17: =(DesignSheet!C11*DesignSheet!C13)*SIN((A17+DesignSheet!C16)) + (DesignSheet!C7)*SIN((DesignSheet!C11+1)*(A17+DesignSheet!C16)) - (DesignSheet!C6/2)*SIN(ATAN( SIN(DesignSheet!C11*(A17+DesignSheet!C16)) / ( COS(DesignSheet!C11*(A17+DesignSheet!C16)) + (DesignSheet!C11*DesignSheet!C13)/(DesignSheet!C7*(DesignSheet!C11+1)) ) )+(A17+DesignSheet!C16)) -> -0.73636073
A18: =2*PI()*16/(DesignSheet!C9-1) -> 0.27925268 | B18: =(DesignSheet!C11*DesignSheet!C13)*COS((A18+DesignSheet!C16)) + (DesignSheet!C7)*COS((DesignSheet!C11+1)*(A18+DesignSheet!C16)) - (DesignSheet!C6/2)*COS(ATAN( SIN(DesignSheet!C11*(A18+DesignSheet!C16)) / ( COS(DesignSheet!C11*(A18+DesignSheet!C16)) + (DesignSheet!C11*DesignSheet!C13)/(DesignSheet!C7*(DesignSheet!C11+1)) ) )+(A18+DesignSheet!C16)) -> 0.15521244 | C18: =(DesignSheet!C11*DesignSheet!C13)*SIN((A18+DesignSheet!C16)) + (DesignSheet!C7)*SIN((DesignSheet!C11+1)*(A18+DesignSheet!C16)) - (DesignSheet!C6/2)*SIN(ATAN( SIN(DesignSheet!C11*(A18+DesignSheet!C16)) / ( COS(DesignSheet!C11*(A18+DesignSheet!C16)) + (DesignSheet!C11*DesignSheet!C13)/(DesignSheet!C7*(DesignSheet!C11+1)) ) )+(A18+DesignSheet!C16)) -> -0.73376365
A19: =2*PI()*17/(DesignSheet!C9-1) -> 0.29670597 | B19: =(DesignSheet!C11*DesignSheet!C13)*COS((A19+DesignSheet!C16)) + (DesignSheet!C7)*COS((DesignSheet!C11+1)*(A19+DesignSheet!C16)) - (DesignSheet!C6/2)*COS(ATAN( SIN(DesignSheet!C11*(A19+DesignSheet!C16)) / ( COS(DesignSheet!C11*(A19+DesignSheet!C16)) + (DesignSheet!C11*DesignSheet!C13)/(DesignSheet!C7*(DesignSheet!C11+1)) ) )+(A19+DesignSheet!C16)) -> 0.16799474 | C19: =(DesignSheet!C11*DesignSheet!C13)*SIN((A19+DesignSheet!C16)) + (DesignSheet!C7)*SIN((DesignSheet!C11+1)*(A19+DesignSheet!C16)) - (DesignSheet!C6/2)*SIN(ATAN( SIN(DesignSheet!C11*(A19+DesignSheet!C16)) / ( COS(DesignSheet!C11*(A19+DesignSheet!C16)) + (DesignSheet!C11*DesignSheet!C13)/(DesignSheet!C7*(DesignSheet!C11+1)) ) )+(A19+DesignSheet!C16)) -> -0.73094307
A20: =2*PI()*18/(DesignSheet!C9-1) -> 0.31415927 | B20: =(DesignSheet!C11*DesignSheet!C13)*COS((A20+DesignSheet!C16)) + (DesignSheet!C7)*COS((DesignSheet!C11+1)*(A20+DesignSheet!C16)) - (DesignSheet!C6/2)*COS(ATAN( SIN(DesignSheet!C11*(A20+DesignSheet!C16)) / ( COS(DesignSheet!C11*(A20+DesignSheet!C16)) + (DesignSheet!C11*DesignSheet!C13)/(DesignSheet!C7*(DesignSheet!C11+1)) ) )+(A20+DesignSheet!C16)) -> 0.18072587 | C20: =(DesignSheet!C11*DesignSheet!C13)*SIN((A20+DesignSheet!C16)) + (DesignSheet!C7)*SIN((DesignSheet!C11+1)*(A20+DesignSheet!C16)) - (DesignSheet!C6/2)*SIN(ATAN( SIN(DesignSheet!C11*(A20+DesignSheet!C16)) / ( COS(DesignSheet!C11*(A20+DesignSheet!C16)) + (DesignSheet!C11*DesignSheet!C13)/(DesignSheet!C7*(DesignSheet!C11+1)) ) )+(A20+DesignSheet!C16)) -> -0.72789983
A21: =2*PI()*19/(DesignSheet!C9-1) -> 0.33161256 | B21: =(DesignSheet!C11*DesignSheet!C13)*COS((A21+DesignSheet!C16)) + (DesignSheet!C7)*COS((DesignSheet!C11+1)*(A21+DesignSheet!C16)) - (DesignSheet!C6/2)*COS(ATAN( SIN(DesignSheet!C11*(A21+DesignSheet!C16)) / ( COS(DesignSheet!C11*(A21+DesignSheet!C16)) + (DesignSheet!C11*DesignSheet!C13)/(DesignSheet!C7*(DesignSheet!C11+1)) ) )+(A21+DesignSheet!C16)) -> 0.19340195 | C21: =(DesignSheet!C11*DesignSheet!C13)*SIN((A21+DesignSheet!C16)) + (DesignSheet!C7)*SIN((DesignSheet!C11+1)*(A21+DesignSheet!C16)) - (DesignSheet!C6/2)*SIN(ATAN( SIN(DesignSheet!C11*(A21+DesignSheet!C16)) / ( COS(DesignSheet!C11*(A21+DesignSheet!C16)) + (DesignSheet!C11*DesignSheet!C13)/(DesignSheet!C7*(DesignSheet!C11+1)) ) )+(A21+DesignSheet!C16)) -> -0.72463486
A22: =2*PI()*20/(DesignSheet!C9-1) -> 0.34906585 | B22: =(DesignSheet!C11*DesignSheet!C13)*COS((A22+DesignSheet!C16)) + (DesignSheet!C7)*COS((DesignSheet!C11+1)*(A22+DesignSheet!C16)) - (DesignSheet!C6/2)*COS(ATAN( SIN(DesignSheet!C11*(A22+DesignSheet!C16)) / ( COS(DesignSheet!C11*(A22+DesignSheet!C16)) + (DesignSheet!C11*DesignSheet!C13)/(DesignSheet!C7*(DesignSheet!C11+1)) ) )+(A22+DesignSheet!C16)) -> 0.20601911 | C22: =(DesignSheet!C11*DesignSheet!C13)*SIN((A22+DesignSheet!C16)) + (DesignSheet!C7)*SIN((DesignSheet!C11+1)*(A22+DesignSheet!C16)) - (DesignSheet!C6/2)*SIN(ATAN( SIN(DesignSheet!C11*(A22+DesignSheet!C16)) / ( COS(DesignSheet!C11*(A22+DesignSheet!C16)) + (DesignSheet!C11*DesignSheet!C13)/(DesignSheet!C7*(DesignSheet!C11+1)) ) )+(A22+DesignSheet!C16)) -> -0.72114917
A23: =2*PI()*21/(DesignSheet!C9-1) -> 0.36651914 | B23: =(DesignSheet!C11*DesignSheet!C13)*COS((A23+DesignSheet!C16)) + (DesignSheet!C7)*COS((DesignSheet!C11+1)*(A23+DesignSheet!C16)) - (DesignSheet!C6/2)*COS(ATAN( SIN(DesignSheet!C11*(A23+DesignSheet!C16)) / ( COS(DesignSheet!C11*(A23+DesignSheet!C16)) + (DesignSheet!C11*DesignSheet!C13)/(DesignSheet!C7*(DesignSheet!C11+1)) ) )+(A23+DesignSheet!C16)) -> 0.21857352 | C23: =(DesignSheet!C11*DesignSheet!C13)*SIN((A23+DesignSheet!C16)) + (DesignSheet!C7)*SIN((DesignSheet!C11+1)*(A23+DesignSheet!C16)) - (DesignSheet!C6/2)*SIN(ATAN( SIN(DesignSheet!C11*(A23+DesignSheet!C16)) / ( COS(DesignSheet!C11*(A23+DesignSheet!C16)) + (DesignSheet!C11*DesignSheet!C13)/(DesignSheet!C7*(DesignSheet!C11+1)) ) )+(A23+DesignSheet!C16)) -> -0.71744381
A24: =2*PI()*22/(DesignSheet!C9-1) -> 0.38397244 | B24: =(DesignSheet!C11*DesignSheet!C13)*COS((A24+DesignSheet!C16)) + (DesignSheet!C7)*COS((DesignSheet!C11+1)*(A24+DesignSheet!C16)) - (DesignSheet!C6/2)*COS(ATAN( SIN(DesignSheet!C11*(A24+DesignSheet!C16)) / ( COS(DesignSheet!C11*(A24+DesignSheet!C16)) + (DesignSheet!C11*DesignSheet!C13)/(DesignSheet!C7*(DesignSheet!C11+1)) ) )+(A24+DesignSheet!C16)) -> 0.23106136 | C24: =(DesignSheet!C11*DesignSheet!C13)*SIN((A24+DesignSheet!C16)) + (DesignSheet!C7)*SIN((DesignSheet!C11+1)*(A24+DesignSheet!C16)) - (DesignSheet!C6/2)*SIN(ATAN( SIN(DesignSheet!C11*(A24+DesignSheet!C16)) / ( COS(DesignSheet!C11*(A24+DesignSheet!C16)) + (DesignSheet!C11*DesignSheet!C13)/(DesignSheet!C7*(DesignSheet!C11+1)) ) )+(A24+DesignSheet!C16)) -> -0.7135199
A25: =2*PI()*23/(DesignSheet!C9-1) -> 0.40142573 | B25: =(DesignSheet!C11*DesignSheet!C13)*COS((A25+DesignSheet!C16)) + (DesignSheet!C7)*COS((DesignSheet!C11+1)*(A25+DesignSheet!C16)) - (DesignSheet!C6/2)*COS(ATAN( SIN(DesignSheet!C11*(A25+DesignSheet!C16)) / ( COS(DesignSheet!C11*(A25+DesignSheet!C16)) + (DesignSheet!C11*DesignSheet!C13)/(DesignSheet!C7*(DesignSheet!C11+1)) ) )+(A25+DesignSheet!C16)) -> 0.2434788 | C25: =(DesignSheet!C11*DesignSheet!C13)*SIN((A25+DesignSheet!C16)) + (DesignSheet!C7)*SIN((DesignSheet!C11+1)*(A25+DesignSheet!C16)) - (DesignSheet!C6/2)*SIN(ATAN( SIN(DesignSheet!C11*(A25+DesignSheet!C16)) / ( COS(DesignSheet!C11*(A25+DesignSheet!C16)) + (DesignSheet!C11*DesignSheet!C13)/(DesignSheet!C7*(DesignSheet!C11+1)) ) )+(A25+DesignSheet!C16)) -> -0.70937865
A26: =2*PI()*24/(DesignSheet!C9-1) -> 0.41887902 | B26: =(DesignSheet!C11*DesignSheet!C13)*COS((A26+DesignSheet!C16)) + (DesignSheet!C7)*COS((DesignSheet!C11+1)*(A26+DesignSheet!C16)) - (DesignSheet!C6/2)*COS(ATAN( SIN(DesignSheet!C11*(A26+DesignSheet!C16)) / ( COS(DesignSheet!C11*(A26+DesignSheet!C16)) + (DesignSheet!C11*DesignSheet!C13)/(DesignSheet!C7*(DesignSheet!C11+1)) ) )+(A26+DesignSheet!C16)) -> 0.25582208 | C26: =(DesignSheet!C11*DesignSheet!C13)*SIN((A26+DesignSheet!C16)) + (DesignSheet!C7)*SIN((DesignSheet!C11+1)*(A26+DesignSheet!C16)) - (DesignSheet!C6/2)*SIN(ATAN( SIN(DesignSheet!C11*(A26+DesignSheet!C16)) / ( COS(DesignSheet!C11*(A26+DesignSheet!C16)) + (DesignSheet!C11*DesignSheet!C13)/(DesignSheet!C7*(DesignSheet!C11+1)) ) )+(A26+DesignSheet!C16)) -> -0.70502132
A27: =2*PI()*25/(DesignSheet!C9-1) -> 0.43633231 | B27: =(DesignSheet!C11*DesignSheet!C13)*COS((A27+DesignSheet!C16)) + (DesignSheet!C7)*COS((DesignSheet!C11+1)*(A27+DesignSheet!C16)) - (DesignSheet!C6/2)*COS(ATAN( SIN(DesignSheet!C11*(A27+DesignSheet!C16)) / ( COS(DesignSheet!C11*(A27+DesignSheet!C16)) + (DesignSheet!C11*DesignSheet!C13)/(DesignSheet!C7*(DesignSheet!C11+1)) ) )+(A27+DesignSheet!C16)) -> 0.26808744 | C27: =(DesignSheet!C11*DesignSheet!C13)*SIN((A27+DesignSheet!C16)) + (DesignSheet!C7)*SIN((DesignSheet!C11+1)*(A27+DesignSheet!C16)) - (DesignSheet!C6/2)*SIN(ATAN( SIN(DesignSheet!C11*(A27+DesignSheet!C16)) / ( COS(DesignSheet!C11*(A27+DesignSheet!C16)) + (DesignSheet!C11*DesignSheet!C13)/(DesignSheet!C7*(DesignSheet!C11+1)) ) )+(A27+DesignSheet!C16)) -> -0.70044923
A28: =2*PI()*26/(DesignSheet!C9-1) -> 0.45378561 | B28: =(DesignSheet!C11*DesignSheet!C13)*COS((A28+DesignSheet!C16)) + (DesignSheet!C7)*COS((DesignSheet!C11+1)*(A28+DesignSheet!C16)) - (DesignSheet!C6/2)*COS(ATAN( SIN(DesignSheet!C11*(A28+DesignSheet!C16)) / ( COS(DesignSheet!C11*(A28+DesignSheet!C16)) + (DesignSheet!C11*DesignSheet!C13)/(DesignSheet!C7*(DesignSheet!C11+1)) ) )+(A28+DesignSheet!C16)) -> 0.28027113 | C28: =(DesignSheet!C11*DesignSheet!C13)*SIN((A28+DesignSheet!C16)) + (DesignSheet!C7)*SIN((DesignSheet!C11+1)*(A28+DesignSheet!C16)) - (DesignSheet!C6/2)*SIN(ATAN( SIN(DesignSheet!C11*(A28+DesignSheet!C16)) / ( COS(DesignSheet!C11*(A28+DesignSheet!C16)) + (DesignSheet!C11*DesignSheet!C13)/(DesignSheet!C7*(DesignSheet!C11+1)) ) )+(A28+DesignSheet!C16)) -> -0.69566378
A29: =2*PI()*27/(DesignSheet!C9-1) -> 0.4712389 | B29: =(DesignSheet!C11*DesignSheet!C13)*COS((A29+DesignSheet!C16)) + (DesignSheet!C7)*COS((DesignSheet!C11+1)*(A29+DesignSheet!C16)) - (DesignSheet!C6/2)*COS(ATAN( SIN(DesignSheet!C11*(A29+DesignSheet!C16)) / ( COS(DesignSheet!C11*(A29+DesignSheet!C16)) + (DesignSheet!C11*DesignSheet!C13)/(DesignSheet!C7*(DesignSheet!C11+1)) ) )+(A29+DesignSheet!C16)) -> 0.29236945 | C29: =(DesignSheet!C11*DesignSheet!C13)*SIN((A29+DesignSheet!C16)) + (DesignSheet!C7)*SIN((DesignSheet!C11+1)*(A29+DesignSheet!C16)) - (DesignSheet!C6/2)*SIN(ATAN( SIN(DesignSheet!C11*(A29+DesignSheet!C16)) / ( COS(DesignSheet!C11*(A29+DesignSheet!C16)) + (DesignSheet!C11*DesignSheet!C13)/(DesignSheet!C7*(DesignSheet!C11+1)) ) )+(A29+DesignSheet!C16)) -> -0.69066642
A30: =2*PI()*28/(DesignSheet!C9-1) -> 0.48869219 | B30: =(DesignSheet!C11*DesignSheet!C13)*COS((A30+DesignSheet!C16)) + (DesignSheet!C7)*COS((DesignSheet!C11+1)*(A30+DesignSheet!C16)) - (DesignSheet!C6/2)*COS(ATAN( SIN(DesignSheet!C11*(A30+DesignSheet!C16)) / ( COS(DesignSheet!C11*(A30+DesignSheet!C16)) + (DesignSheet!C11*DesignSheet!C13)/(DesignSheet!C7*(DesignSheet!C11+1)) ) )+(A30+DesignSheet!C16)) -> 0.30437872 | C30: =(DesignSheet!C11*DesignSheet!C13)*SIN((A30+DesignSheet!C16)) + (DesignSheet!C7)*SIN((DesignSheet!C11+1)*(A30+DesignSheet!C16)) - (DesignSheet!C6/2)*SIN(ATAN( SIN(DesignSheet!C11*(A30+DesignSheet!C16)) / ( COS(DesignSheet!C11*(A30+DesignSheet!C16)) + (DesignSheet!C11*DesignSheet!C13)/(DesignSheet!C7*(DesignSheet!C11+1)) ) )+(A30+DesignSheet!C16)) -> -0.68545868
A31: =2*PI()*29/(DesignSheet!C9-1) -> 0.50614548 | B31: =(DesignSheet!C11*DesignSheet!C13)*COS((A31+DesignSheet!C16)) + (DesignSheet!C7)*COS((DesignSheet!C11+1)*(A31+DesignSheet!C16)) - (DesignSheet!C6/2)*COS(ATAN( SIN(DesignSheet!C11*(A31+DesignSheet!C16)) / ( COS(DesignSheet!C11*(A31+DesignSheet!C16)) + (DesignSheet!C11*DesignSheet!C13)/(DesignSheet!C7*(DesignSheet!C11+1)) ) )+(A31+DesignSheet!C16)) -> 0.31629526 | C31: =(DesignSheet!C11*DesignSheet!C13)*SIN((A31+DesignSheet!C16)) + (DesignSheet!C7)*SIN((DesignSheet!C11+1)*(A31+DesignSheet!C16)) - (DesignSheet!C6/2)*SIN(ATAN( SIN(DesignSheet!C11*(A31+DesignSheet!C16)) / ( COS(DesignSheet!C11*(A31+DesignSheet!C16)) + (DesignSheet!C11*DesignSheet!C13)/(DesignSheet!C7*(DesignSheet!C11+1)) ) )+(A31+DesignSheet!C16)) -> -0.68004214
A32: =2*PI()*30/(DesignSheet!C9-1) -> 0.52359878 | B32: =(DesignSheet!C11*DesignSheet!C13)*COS((A32+DesignSheet!C16)) + (DesignSheet!C7)*COS((DesignSheet!C11+1)*(A32+DesignSheet!C16)) - (DesignSheet!C6/2)*COS(ATAN( SIN(DesignSheet!C11*(A32+DesignSheet!C16)) / ( COS(DesignSheet!C11*(A32+DesignSheet!C16)) + (DesignSheet!C11*DesignSheet!C13)/(DesignSheet!C7*(DesignSheet!C11+1)) ) )+(A32+DesignSheet!C16)) -> 0.32811546 | C32: =(DesignSheet!C11*DesignSheet!C13)*SIN((A32+DesignSheet!C16)) + (DesignSheet!C7)*SIN((DesignSheet!C11+1)*(A32+DesignSheet!C16)) - (DesignSheet!C6/2)*SIN(ATAN( SIN(DesignSheet!C11*(A32+DesignSheet!C16)) / ( COS(DesignSheet!C11*(A32+DesignSheet!C16)) + (DesignSheet!C11*DesignSheet!C13)/(DesignSheet!C7*(DesignSheet!C11+1)) ) )+(A32+DesignSheet!C16)) -> -0.67441845
A33: =2*PI()*31/(DesignSheet!C9-1) -> 0.54105207 | B33: =(DesignSheet!C11*DesignSheet!C13)*COS((A33+DesignSheet!C16)) + (DesignSheet!C7)*COS((DesignSheet!C11+1)*(A33+DesignSheet!C16)) - (DesignSheet!C6/2)*COS(ATAN( SIN(DesignSheet!C11*(A33+DesignSheet!C16)) / ( COS(DesignSheet!C11*(A33+DesignSheet!C16)) + (DesignSheet!C11*DesignSheet!C13)/(DesignSheet!C7*(DesignSheet!C11+1)) ) )+(A33+DesignSheet!C16)) -> 0.33983571 | C33: =(DesignSheet!C11*DesignSheet!C13)*SIN((A33+DesignSheet!C16)) + (DesignSheet!C7)*SIN((DesignSheet!C11+1)*(A33+DesignSheet!C16)) - (DesignSheet!C6/2)*SIN(ATAN( SIN(DesignSheet!C11*(A33+DesignSheet!C16)) / ( COS(DesignSheet!C11*(A33+DesignSheet!C16)) + (DesignSheet!C11*DesignSheet!C13)/(DesignSheet!C7*(DesignSheet!C11+1)) ) )+(A33+DesignSheet!C16)) -> -0.66858933
A34: =2*PI()*32/(DesignSheet!C9-1) -> 0.55850536 | B34: =(DesignSheet!C11*DesignSheet!C13)*COS((A34+DesignSheet!C16)) + (DesignSheet!C7)*COS((DesignSheet!C11+1)*(A34+DesignSheet!C16)) - (DesignSheet!C6/2)*COS(ATAN( SIN(DesignSheet!C11*(A34+DesignSheet!C16)) / ( COS(DesignSheet!C11*(A34+DesignSheet!C16)) + (DesignSheet!C11*DesignSheet!C13)/(DesignSheet!C7*(DesignSheet!C11+1)) ) )+(A34+DesignSheet!C16)) -> 0.35145245 | C34: =(DesignSheet!C11*DesignSheet!C13)*SIN((A34+DesignSheet!C16)) + (DesignSheet!C7)*SIN((DesignSheet!C11+1)*(A34+DesignSheet!C16)) - (DesignSheet!C6/2)*SIN(ATAN( SIN(DesignSheet!C11*(A34+DesignSheet!C16)) / ( COS(DesignSheet!C11*(A34+DesignSheet!C16)) + (DesignSheet!C11*DesignSheet!C13)/(DesignSheet!C7*(DesignSheet!C11+1)) ) )+(A34+DesignSheet!C16)) -> -0.66255655
A35: =2*PI()*33/(DesignSheet!C9-1) -> 0.57595865 | B35: =(DesignSheet!C11*DesignSheet!C13)*COS((A35+DesignSheet!C16)) + (DesignSheet!C7)*COS((DesignSheet!C11+1)*(A35+DesignSheet!C16)) - (DesignSheet!C6/2)*COS(ATAN( SIN(DesignSheet!C11*(A35+DesignSheet!C16)) / ( COS(DesignSheet!C11*(A35+DesignSheet!C16)) + (DesignSheet!C11*DesignSheet!C13)/(DesignSheet!C7*(DesignSheet!C11+1)) ) )+(A35+DesignSheet!C16)) -> 0.36296212 | C35: =(DesignSheet!C11*DesignSheet!C13)*SIN((A35+DesignSheet!C16)) + (DesignSheet!C7)*SIN((DesignSheet!C11+1)*(A35+DesignSheet!C16)) - (DesignSheet!C6/2)*SIN(ATAN( SIN(DesignSheet!C11*(A35+DesignSheet!C16)) / ( COS(DesignSheet!C11*(A35+DesignSheet!C16)) + (DesignSheet!C11*DesignSheet!C13)/(DesignSheet!C7*(DesignSheet!C11+1)) ) )+(A35+DesignSheet!C16)) -> -0.65632195
A36: =2*PI()*34/(DesignSheet!C9-1) -> 0.59341195 | B36: =(DesignSheet!C11*DesignSheet!C13)*COS((A36+DesignSheet!C16)) + (DesignSheet!C7)*COS((DesignSheet!C11+1)*(A36+DesignSheet!C16)) - (DesignSheet!C6/2)*COS(ATAN( SIN(DesignSheet!C11*(A36+DesignSheet!C16)) / ( COS(DesignSheet!C11*(A36+DesignSheet!C16)) + (DesignSheet!C11*DesignSheet!C13)/(DesignSheet!C7*(DesignSheet!C11+1)) ) )+(A36+DesignSheet!C16)) -> 0.37436124 | C36: =(DesignSheet!C11*DesignSheet!C13)*SIN((A36+DesignSheet!C16)) + (DesignSheet!C7)*SIN((DesignSheet!C11+1)*(A36+DesignSheet!C16)) - (DesignSheet!C6/2)*SIN(ATAN( SIN(DesignSheet!C11*(A36+DesignSheet!C16)) / ( COS(DesignSheet!C11*(A36+DesignSheet!C16)) + (DesignSheet!C11*DesignSheet!C13)/(DesignSheet!C7*(DesignSheet!C11+1)) ) )+(A36+DesignSheet!C16)) -> -0.64988742
A37: =2*PI()*35/(DesignSheet!C9-1) -> 0.61086524 | B37: =(DesignSheet!C11*DesignSheet!C13)*COS((A37+DesignSheet!C16)) + (DesignSheet!C7)*COS((DesignSheet!C11+1)*(A37+DesignSheet!C16)) - (DesignSheet!C6/2)*COS(ATAN( SIN(DesignSheet!C11*(A37+DesignSheet!C16)) / ( COS(DesignSheet!C11*(A37+DesignSheet!C16)) + (DesignSheet!C11*DesignSheet!C13)/(DesignSheet!C7*(DesignSheet!C11+1)) ) )+(A37+DesignSheet!C16)) -> 0.38564632 | C37: =(DesignSheet!C11*DesignSheet!C13)*SIN((A37+DesignSheet!C16)) + (DesignSheet!C7)*SIN((DesignSheet!C11+1)*(A37+DesignSheet!C16)) - (DesignSheet!C6/2)*SIN(ATAN( SIN(DesignSheet!C11*(A37+DesignSheet!C16)) / ( COS(DesignSheet!C11*(A37+DesignSheet!C16)) + (DesignSheet!C11*DesignSheet!C13)/(DesignSheet!C7*(DesignSheet!C11+1)) ) )+(A37+DesignSheet!C16)) -> -0.64325494
A38: =2*PI()*36/(DesignSheet!C9-1) -> 0.62831853 | B38: =(DesignSheet!C11*DesignSheet!C13)*COS((A38+DesignSheet!C16)) + (DesignSheet!C7)*COS((DesignSheet!C11+1)*(A38+DesignSheet!C16)) - (DesignSheet!C6/2)*COS(ATAN( SIN(DesignSheet!C11*(A38+DesignSheet!C16)) / ( COS(DesignSheet!C11*(A38+DesignSheet!C16)) + (DesignSheet!C11*DesignSheet!C13)/(DesignSheet!C7*(DesignSheet!C11+1)) ) )+(A38+DesignSheet!C16)) -> 0.39681393 | C38: =(DesignSheet!C11*DesignSheet!C13)*SIN((A38+DesignSheet!C16)) + (DesignSheet!C7)*SIN((DesignSheet!C11+1)*(A38+DesignSheet!C16)) - (DesignSheet!C6/2)*SIN(ATAN( SIN(DesignSheet!C11*(A38+DesignSheet!C16)) / ( COS(DesignSheet!C11*(A38+DesignSheet!C16)) + (DesignSheet!C11*DesignSheet!C13)/(DesignSheet!C7*(DesignSheet!C11+1)) ) )+(A38+DesignSheet!C16)) -> -0.63642651
A39: =2*PI()*37/(DesignSheet!C9-1) -> 0.64577182 | B39: =(DesignSheet!C11*DesignSheet!C13)*COS((A39+DesignSheet!C16)) + (DesignSheet!C7)*COS((DesignSheet!C11+1)*(A39+DesignSheet!C16)) - (DesignSheet!C6/2)*COS(ATAN( SIN(DesignSheet!C11*(A39+DesignSheet!C16)) / ( COS(DesignSheet!C11*(A39+DesignSheet!C16)) + (DesignSheet!C11*DesignSheet!C13)/(DesignSheet!C7*(DesignSheet!C11+1)) ) )+(A39+DesignSheet!C16)) -> 0.40786067 | C39: =(DesignSheet!C11*DesignSheet!C13)*SIN((A39+DesignSheet!C16)) + (DesignSheet!C7)*SIN((DesignSheet!C11+1)*(A39+DesignSheet!C16)) - (DesignSheet!C6/2)*SIN(ATAN( SIN(DesignSheet!C11*(A39+DesignSheet!C16)) / ( COS(DesignSheet!C11*(A39+DesignSheet!C16)) + (DesignSheet!C11*DesignSheet!C13)/(DesignSheet!C7*(DesignSheet!C11+1)) ) )+(A39+DesignSheet!C16)) -> -0.62940422
A40: =2*PI()*38/(DesignSheet!C9-1) -> 0.66322512 | B40: =(DesignSheet!C11*DesignSheet!C13)*COS((A40+DesignSheet!C16)) + (DesignSheet!C7)*COS((DesignSheet!C11+1)*(A40+DesignSheet!C16)) - (DesignSheet!C6/2)*COS(ATAN( SIN(DesignSheet!C11*(A40+DesignSheet!C16)) / ( COS(DesignSheet!C11*(A40+DesignSheet!C16)) + (DesignSheet!C11*DesignSheet!C13)/(DesignSheet!C7*(DesignSheet!C11+1)) ) )+(A40+DesignSheet!C16)) -> 0.41878317 | C40: =(DesignSheet!C11*DesignSheet!C13)*SIN((A40+DesignSheet!C16)) + (DesignSheet!C7)*SIN((DesignSheet!C11+1)*(A40+DesignSheet!C16)) - (DesignSheet!C6/2)*SIN(ATAN( SIN(DesignSheet!C11*(A40+DesignSheet!C16)) / ( COS(DesignSheet!C11*(A40+DesignSheet!C16)) + (DesignSheet!C11*DesignSheet!C13)/(DesignSheet!C7*(DesignSheet!C11+1)) ) )+(A40+DesignSheet!C16)) -> -0.62219021
...
